# **_예외처리_**

### **_자바의 정석 내용 정리_**

우선 에러에는 "컴파일 에러"와 "런타임 에러"로 나눠진다. ("논리적 에러"가 존재하지만 이것은 실행은 되지만 의도와는 다르게 동작하는 것을 의미)

"컴파일 에러"는 컴파일 과정중에 발생한 에러를 의미하며, 컴파일러가 전체적인 코드에 대해 컴파일을 하면서 에러를 찾아준다.

"런타임 에러"는 프로그램 실행 도중에 발생하는 에러를 의미하는데, "런타임 에러"는 **_에러(error)_** 와 **_예외(Exception)_** 으로 나눠진다.

"에러"는 프로그램 코드로 수습이 불가능한 심각한 오류를 의미하고, "예외"는 프로그램 코드로 수습이 가능한 미약한 오류를 의미한다.

컴파일 에러와 런타임 에러중에 발생한 "에러"는 프로그램 코드를 추가해서 수습할 수 있는 에러가 아니므로 해당 챕터에서 공부하고자 하는 내용은 바로 "예외"부분이다.

</br>

  <p align = "center"><img src="https://user-images.githubusercontent.com/62879192/188267091-48d63675-29bf-4750-958d-c526e276ef4e.png" height = 250px></p>

자바에서 발생할 수 있는 에러는 위와 같이 종류가 다양하며, 최상위 클래스 Object 클래스를 상속받는다.

이중에서 봐야하는 부분은 Exception 즉 개발자가 컨트롤할 수 있는 예외부분이다.

예외처리는 프로그램 실행 시 발생하는 예외에 대한 대비를 하기 위해 코드를 작성하는 것이고, 예외처리를 안해주면 해당 예외가 발생할 시에 프로그램은 종료가 된다. (JVM내에 존재하는 예외처리기에 의해 원인을 화면에 출력해줌)

예외 처리를 할 때에는 try-catch문을 사용하며, try안에는 예외가 발생할 수 있는 코드들을 catch의 괄호에는 예외에 맞는 타입의 참조변수를 선언한다.  
다수의 catch문이 존재할 수 있으며, 예외가 발샐할 시에는 예외에 맞는 클래스에 의한 인스턴스가 만들어지고 이를 catch문의 타입과의 instanceOf연산자로 비교하여 참인 catch문 **_단 하나_** 만을 실행하고 try-catch문을 빠져나간다.

이러한 비교방식에 의해서 Exception e 와같이 모든 예외의 부모클래스의 참조변수로 선언하면 어떤 예외가 발생하는 catch문이 실행이 되는 것이다.

```java
public class ExceptionEx1 {
    public static void main(String[] args) {
        try{
            System.out.println(1);
            System.out.println(0/0); //ArithmeticException 발생
            System.out.println(2);
        }catch(ArithmeticException e){
            System.out.println(3);
            e.printStackTrace(); //예외발생 당시의 호출스택의 메서드 및 예외에 대한 정보를 반환
            System.out.println("예외 : " + e.getMessage()); //에러 내용 반환
        }catch(Exception e){
            System.out.println("ArithmeticException 이외의 모든 예외 처리");
        }
    }
}

실행결과 :
1
3
java.lang.ArithmeticException: / by zero
	at chapter8.ExceptionEx1.main(ExceptionEx1.java:7)

예외 : / by zero

```

위처럼 예외가 발생한 위치에서 아래의 코드를 실행하지 않고 바로 catch문으로 가서 발생한 예외에 대한 처리가 있는지 찾는다.  
찾았으면 내부의 코드를 실행시키며 참조변수를 통하여 위와같이 e.printStackTrace() 나 e.getMessage()로 예외에 대한 여러 정보들을 확인할 수 있다.

</br>

---

## **_멀티 catch 블럭_**

```java
try{
    //예외 발생 가능한 코드
}catch(ExceptionA | ExceptionB e){
    //예외처리 코드
}
```

멀티 catch 블럭은 위와같이 catch ()안에 발생할 수 있는 예외클래스들을 여러개를 묶어서 하나의 참조변수로 받아서 처리하는 구문이다.

하지만 이러한 처리방식에 문제가 있는데, ExceptionA에 의해 catch문이 실행되는지 아니면 ExceptionB에서 실행되는지를 알기가 어렵다는 것이다.

그렇기 때문에 컴파일러 또한 두 예외클래스의 공통 분모의 부모클래스의 메서드만 사용이 가능하며, 각 예외 클래스에 존재하는 메서드를 사용하기 위해서는 if(e instanceOf ExceptionA) 와 같이 정확히 발생한 클래스에 대해 판별한 후에 사용이 가능하다.

</br>

---

## **_에외 발생시키기_**

```java
예외 발생시키는 방법 2가지

Exception e = new Exception("에러 발생");
throw e;

or

throw new Exception("에러 발생");

-------------------------------------

try{
    throw new ArithmeticException("에러 발생!");
}catch (Exception e){
    e.printStackTrace();
}
```

위와 같이 고의로 예외를 발생시켜서 처리할 수가 있다.

</br>

---

## **_checked예외, unchecked 예외_**

```java
checked예외

public static void main(String[] args) {
    throw new Exception("에러");
}

-------------------------------------------------
unchecked예외

public static void main(String[] args) {
    throw new RuntimeException("런타임 에러");
}
```

위처럼 에외에도 두가지 종류로 나눠진다.  
RuntimeException 클래스에 포함되는 클래스들은 전부 unchecked예외이며, 이외의 모든 예외는 checked예외이다.

위 두가지의 차이점은 checked예외의 경우에는 예외처리(try-catch)를 하지않으면 컴파일 과정에서 에러가 발생하지만, unchecked예외의 경우에는 런타임 에러에 속하기 때문에 예외처리를 따로 하지 않아도 컴파일이 진행이 되고, 실행이 이루어진다.(하지만 결국 예외가 발생했을 때에는 그에대한 처리구문이 존재해야함)

또한 트랜잭션의 롤백여부에의 차이도 존재

</br>

---

## **_메서드에서 예외 선언하는 방식_**

```java

void method() throws ExceptionA, ExceptionB {
    //구현부
}

```

위와 같이 메서드 선언부에 처리해야할 예외들을 명시할 수 있으며, 위처럼 명시할 경우에 해당 메서드를 호출하는 쪽에서 예외처리를 해줘야한다.

이러한 방식의 장점으로는 메서드의 선언부만을 통해 해당 메서드에서 발생할 수 있는 예외에 대해 알 수 있다는 점이다.

단점으로는, open-close를 위배한다는 것. 그러니까 해당 메서드를 호출하는 쪽에서 예외처리를 해줘야 한다는 것은 상위 메서드가 하위메서드에 대한 코드를 알아야한다는 것 그리고 상위 메서드의 책임감 증가 등 여러 문제가 발생할 수 있기 때문에 정말로 필요한 경우가 아니면 이 방식은 한번 더 고려해봐야 한다.

</br>

---

## **_finally 블럭_**

```java
public class finallyExceptionEx {
    public static void main(String[] args) {
        try{
            method1();
        } catch (Exception e){
            System.out.println(5);
        }
    }

    static void method1(){
        try{
            method2();
            System.out.println(1);
        }catch(ArithmeticException e){
            System.out.println(2);
        }finally {
            System.out.println(3);
        }

        System.out.println(4);
    }

    static void method2(){
        throw new NullPointerException();
    }
}

실행결과 :
3
5
```

위 코드를 통해 finally블럭의 흐름을 알 수 있다.

main -> method1 -> method2 순으로 호출스택에 쌓이며 실행이 되고, method2에서 NPE 예외를 던진다.

해당 예외를 받은 method1에서는 1을 출력하지 않고, 바로 catch문에서 일치하는 부분을 찾지만 NPE에 대한 예외는 없기때문에 catch문을 건너뛰고, finally구문을 실행한다. 예외가 발생했지만 catch문을 실행하지 않았기 때문에 아래의 4를 출력하는 부분은 건너뛰고, 바로 main함수로 간다. main함수내에서 최종적으로 catch문이 동작이 되어서 예외처리가 이루어진다.

finally 구문은 예외 여부와 상관없이 무조건 동작이 되며, catch구문이 실행이 이루어지지 않았을 경우 finally구문까지만 실행하고 아래의 코드들은 실행되지 않은채 method 실행을 종료한다.

</br>

---

## **_사용자 정의 예외_**

```java
public class CustomExceptionEx {
    public static void main(String[] args) {
        try{
            CustomExceptionEx.tt();
        }catch (CustomException e){
            System.out.println("4");
        }
    }

    public static void tt(){
        try{
            throw new RuntimeException("에러 발생");
        }catch(RuntimeException e){
            System.out.println("2");
            throw new CustomException(e.getMessage());
        }
        //System.out.println("3"); 컴파일 에러 -> catch 구문에서 새로운 예외를 던지기 때문에 이하 코드는 실행이 되지 않음.
    }
}

class CustomException extends RuntimeException{
    private final int ERR_CODE;

    public CustomException(String msg){
        this(msg,500);
    }

    public CustomException(String msg, int errCode){
        super(msg);
        this.ERR_CODE = errCode;
    }

    public void printErrCode(){
        System.out.println(this.ERR_CODE);
    }
}
```

위처럼 사용자 정의로 에외를 만들 수 있으며, tt함수 내에서 catch 구문에서 연결된 예외 즉, 새로운 예외를 던져주는데 위는 RuntimeException이 발생햇을 경우지만 checked 예외 즉 RuntimeException 클래스 외에 예외들에서는 반드시 try-catch구문이 필요하고, catch구문에서는 예외 복구의 방식으로 복구를 하는데 이러한 복구를 못하는 즉, 예외를 처리할 수 없는 상황이 많아지기 시작한 것이다.  
해당 상황에서 할 수 있는건 없는데 무의미한 try-catch구문만 사용하는 것 뿐이다.

하지만 위처럼 unchecked 클래스로 throw를 해줌으로써, 해당 클래스로 예외처리를 따로 처리하게끔 하며 또한, unchecked 클래스이므로 예외처리에 대해 선택적으로 바뀌게 됨으로써 억지로 try-catch구문을 추가하지 않아도 되는 것이다.

</br>

---

## **_추가 공부_**

https://www.nextree.co.kr/p3239/  
에서 예외처리하는 방식은 총 3가지로 예외 복구, 예외처리 회피, 예외 전환이 있다.

예외 복구는 try-catch구문에서 catch구문내에 예외에 대한 복구를 하는 것

예외처리 회피는 메서드 선언부에 throws 로 예외들을 선언함으로써, 상위 메서드한테 책임을 전가하는 방식

예외 전환은 catch 구문 안에 throw로 새로운 예외를 던져줌으로써 다른 예외처리 방식으로 전환하는 것이다.

내가 추가로 공부해야할 부분은 예외 전환에서 throw로 unchecked Exception 클래스로 던져주는데 이러한 이유로

CheckedException 처럼 복구 불가능 Exception을 catch 하여,
UncheckedException 으로 전환하여 Handling 함으로써,
다른 계층에서 CheckedException을 일일히 선언하지 않아도 되게 할 수도 있다.

외의 여러가지 이유가 존재하는데, 실무 또는 직접 사용한 예시를 봐야 이해가 될 것 같다.

</br>

---

# **_참고_**

- https://github.com/GimunLee/tech-refrigerator/blob/master/Language/JAVA/Error%20%26%20Exception.md#error--exception [예외 내용 참고]
